2023-08-06 18:45:34,044 ERROR: Exception on /index [GET] [in /Users/dc/.pyenv/versions/3.11.3/lib/python3.11/site-packages/flask/app.py:1414]
Traceback (most recent call last):
  File "/Users/dc/.pyenv/versions/3.11.3/lib/python3.11/site-packages/sqlalchemy/engine/base.py", line 1965, in _exec_single_context
    self.dialect.do_execute(
  File "/Users/dc/.pyenv/versions/3.11.3/lib/python3.11/site-packages/sqlalchemy/engine/default.py", line 921, in do_execute
    cursor.execute(statement, parameters)
sqlite3.OperationalError: attempt to write a readonly database

The above exception was the direct cause of the following exception:

Traceback (most recent call last):
  File "/Users/dc/.pyenv/versions/3.11.3/lib/python3.11/site-packages/flask/app.py", line 2190, in wsgi_app
    response = self.full_dispatch_request()
               ^^^^^^^^^^^^^^^^^^^^^^^^^^^^
  File "/Users/dc/.pyenv/versions/3.11.3/lib/python3.11/site-packages/flask/app.py", line 1486, in full_dispatch_request
    rv = self.handle_user_exception(e)
         ^^^^^^^^^^^^^^^^^^^^^^^^^^^^^
  File "/Users/dc/.pyenv/versions/3.11.3/lib/python3.11/site-packages/flask/app.py", line 1482, in full_dispatch_request
    rv = self.preprocess_request()
         ^^^^^^^^^^^^^^^^^^^^^^^^^
  File "/Users/dc/.pyenv/versions/3.11.3/lib/python3.11/site-packages/flask/app.py", line 1974, in preprocess_request
    rv = self.ensure_sync(before_func)()
         ^^^^^^^^^^^^^^^^^^^^^^^^^^^^^^^
  File "/Users/dc/test_stuff/flask/ch9/microblog/app/routes.py", line 20, in before_request
    db.session.commit()
  File "/Users/dc/.pyenv/versions/3.11.3/lib/python3.11/site-packages/sqlalchemy/orm/scoping.py", line 552, in commit
    return self._proxied.commit()
           ^^^^^^^^^^^^^^^^^^^^^^
  File "/Users/dc/.pyenv/versions/3.11.3/lib/python3.11/site-packages/sqlalchemy/orm/session.py", line 1920, in commit
    trans.commit(_to_root=True)
  File "<string>", line 2, in commit
  File "/Users/dc/.pyenv/versions/3.11.3/lib/python3.11/site-packages/sqlalchemy/orm/state_changes.py", line 139, in _go
    ret_value = fn(self, *arg, **kw)
                ^^^^^^^^^^^^^^^^^^^^
  File "/Users/dc/.pyenv/versions/3.11.3/lib/python3.11/site-packages/sqlalchemy/orm/session.py", line 1236, in commit
    self._prepare_impl()
  File "<string>", line 2, in _prepare_impl
  File "/Users/dc/.pyenv/versions/3.11.3/lib/python3.11/site-packages/sqlalchemy/orm/state_changes.py", line 139, in _go
    ret_value = fn(self, *arg, **kw)
                ^^^^^^^^^^^^^^^^^^^^
  File "/Users/dc/.pyenv/versions/3.11.3/lib/python3.11/site-packages/sqlalchemy/orm/session.py", line 1211, in _prepare_impl
    self.session.flush()
  File "/Users/dc/.pyenv/versions/3.11.3/lib/python3.11/site-packages/sqlalchemy/orm/session.py", line 4163, in flush
    self._flush(objects)
  File "/Users/dc/.pyenv/versions/3.11.3/lib/python3.11/site-packages/sqlalchemy/orm/session.py", line 4298, in _flush
    with util.safe_reraise():
  File "/Users/dc/.pyenv/versions/3.11.3/lib/python3.11/site-packages/sqlalchemy/util/langhelpers.py", line 147, in __exit__
    raise exc_value.with_traceback(exc_tb)
  File "/Users/dc/.pyenv/versions/3.11.3/lib/python3.11/site-packages/sqlalchemy/orm/session.py", line 4259, in _flush
    flush_context.execute()
  File "/Users/dc/.pyenv/versions/3.11.3/lib/python3.11/site-packages/sqlalchemy/orm/unitofwork.py", line 466, in execute
    rec.execute(self)
  File "/Users/dc/.pyenv/versions/3.11.3/lib/python3.11/site-packages/sqlalchemy/orm/unitofwork.py", line 642, in execute
    util.preloaded.orm_persistence.save_obj(
  File "/Users/dc/.pyenv/versions/3.11.3/lib/python3.11/site-packages/sqlalchemy/orm/persistence.py", line 85, in save_obj
    _emit_update_statements(
  File "/Users/dc/.pyenv/versions/3.11.3/lib/python3.11/site-packages/sqlalchemy/orm/persistence.py", line 909, in _emit_update_statements
    c = connection.execute(
        ^^^^^^^^^^^^^^^^^^^
  File "/Users/dc/.pyenv/versions/3.11.3/lib/python3.11/site-packages/sqlalchemy/engine/base.py", line 1412, in execute
    return meth(
           ^^^^^
  File "/Users/dc/.pyenv/versions/3.11.3/lib/python3.11/site-packages/sqlalchemy/sql/elements.py", line 483, in _execute_on_connection
    return connection._execute_clauseelement(
           ^^^^^^^^^^^^^^^^^^^^^^^^^^^^^^^^^^
  File "/Users/dc/.pyenv/versions/3.11.3/lib/python3.11/site-packages/sqlalchemy/engine/base.py", line 1635, in _execute_clauseelement
    ret = self._execute_context(
          ^^^^^^^^^^^^^^^^^^^^^^
  File "/Users/dc/.pyenv/versions/3.11.3/lib/python3.11/site-packages/sqlalchemy/engine/base.py", line 1844, in _execute_context
    return self._exec_single_context(
           ^^^^^^^^^^^^^^^^^^^^^^^^^^
  File "/Users/dc/.pyenv/versions/3.11.3/lib/python3.11/site-packages/sqlalchemy/engine/base.py", line 1984, in _exec_single_context
    self._handle_dbapi_exception(
  File "/Users/dc/.pyenv/versions/3.11.3/lib/python3.11/site-packages/sqlalchemy/engine/base.py", line 2339, in _handle_dbapi_exception
    raise sqlalchemy_exception.with_traceback(exc_info[2]) from e
  File "/Users/dc/.pyenv/versions/3.11.3/lib/python3.11/site-packages/sqlalchemy/engine/base.py", line 1965, in _exec_single_context
    self.dialect.do_execute(
  File "/Users/dc/.pyenv/versions/3.11.3/lib/python3.11/site-packages/sqlalchemy/engine/default.py", line 921, in do_execute
    cursor.execute(statement, parameters)
sqlalchemy.exc.OperationalError: (sqlite3.OperationalError) attempt to write a readonly database
[SQL: UPDATE user SET last_seen=? WHERE user.id = ?]
[parameters: ('2023-08-07 01:45:34.043123', 2)]
(Background on this error at: https://sqlalche.me/e/20/e3q8)
2023-08-06 18:45:35,152 ERROR: Exception on /index [GET] [in /Users/dc/.pyenv/versions/3.11.3/lib/python3.11/site-packages/flask/app.py:1414]
Traceback (most recent call last):
  File "/Users/dc/.pyenv/versions/3.11.3/lib/python3.11/site-packages/sqlalchemy/engine/base.py", line 1965, in _exec_single_context
    self.dialect.do_execute(
  File "/Users/dc/.pyenv/versions/3.11.3/lib/python3.11/site-packages/sqlalchemy/engine/default.py", line 921, in do_execute
    cursor.execute(statement, parameters)
sqlite3.OperationalError: attempt to write a readonly database

The above exception was the direct cause of the following exception:

Traceback (most recent call last):
  File "/Users/dc/.pyenv/versions/3.11.3/lib/python3.11/site-packages/flask/app.py", line 2190, in wsgi_app
    response = self.full_dispatch_request()
               ^^^^^^^^^^^^^^^^^^^^^^^^^^^^
  File "/Users/dc/.pyenv/versions/3.11.3/lib/python3.11/site-packages/flask/app.py", line 1486, in full_dispatch_request
    rv = self.handle_user_exception(e)
         ^^^^^^^^^^^^^^^^^^^^^^^^^^^^^
  File "/Users/dc/.pyenv/versions/3.11.3/lib/python3.11/site-packages/flask/app.py", line 1482, in full_dispatch_request
    rv = self.preprocess_request()
         ^^^^^^^^^^^^^^^^^^^^^^^^^
  File "/Users/dc/.pyenv/versions/3.11.3/lib/python3.11/site-packages/flask/app.py", line 1974, in preprocess_request
    rv = self.ensure_sync(before_func)()
         ^^^^^^^^^^^^^^^^^^^^^^^^^^^^^^^
  File "/Users/dc/test_stuff/flask/ch9/microblog/app/routes.py", line 20, in before_request
    db.session.commit()
  File "/Users/dc/.pyenv/versions/3.11.3/lib/python3.11/site-packages/sqlalchemy/orm/scoping.py", line 552, in commit
    return self._proxied.commit()
           ^^^^^^^^^^^^^^^^^^^^^^
  File "/Users/dc/.pyenv/versions/3.11.3/lib/python3.11/site-packages/sqlalchemy/orm/session.py", line 1920, in commit
    trans.commit(_to_root=True)
  File "<string>", line 2, in commit
  File "/Users/dc/.pyenv/versions/3.11.3/lib/python3.11/site-packages/sqlalchemy/orm/state_changes.py", line 139, in _go
    ret_value = fn(self, *arg, **kw)
                ^^^^^^^^^^^^^^^^^^^^
  File "/Users/dc/.pyenv/versions/3.11.3/lib/python3.11/site-packages/sqlalchemy/orm/session.py", line 1236, in commit
    self._prepare_impl()
  File "<string>", line 2, in _prepare_impl
  File "/Users/dc/.pyenv/versions/3.11.3/lib/python3.11/site-packages/sqlalchemy/orm/state_changes.py", line 139, in _go
    ret_value = fn(self, *arg, **kw)
                ^^^^^^^^^^^^^^^^^^^^
  File "/Users/dc/.pyenv/versions/3.11.3/lib/python3.11/site-packages/sqlalchemy/orm/session.py", line 1211, in _prepare_impl
    self.session.flush()
  File "/Users/dc/.pyenv/versions/3.11.3/lib/python3.11/site-packages/sqlalchemy/orm/session.py", line 4163, in flush
    self._flush(objects)
  File "/Users/dc/.pyenv/versions/3.11.3/lib/python3.11/site-packages/sqlalchemy/orm/session.py", line 4298, in _flush
    with util.safe_reraise():
  File "/Users/dc/.pyenv/versions/3.11.3/lib/python3.11/site-packages/sqlalchemy/util/langhelpers.py", line 147, in __exit__
    raise exc_value.with_traceback(exc_tb)
  File "/Users/dc/.pyenv/versions/3.11.3/lib/python3.11/site-packages/sqlalchemy/orm/session.py", line 4259, in _flush
    flush_context.execute()
  File "/Users/dc/.pyenv/versions/3.11.3/lib/python3.11/site-packages/sqlalchemy/orm/unitofwork.py", line 466, in execute
    rec.execute(self)
  File "/Users/dc/.pyenv/versions/3.11.3/lib/python3.11/site-packages/sqlalchemy/orm/unitofwork.py", line 642, in execute
    util.preloaded.orm_persistence.save_obj(
  File "/Users/dc/.pyenv/versions/3.11.3/lib/python3.11/site-packages/sqlalchemy/orm/persistence.py", line 85, in save_obj
    _emit_update_statements(
  File "/Users/dc/.pyenv/versions/3.11.3/lib/python3.11/site-packages/sqlalchemy/orm/persistence.py", line 909, in _emit_update_statements
    c = connection.execute(
        ^^^^^^^^^^^^^^^^^^^
  File "/Users/dc/.pyenv/versions/3.11.3/lib/python3.11/site-packages/sqlalchemy/engine/base.py", line 1412, in execute
    return meth(
           ^^^^^
  File "/Users/dc/.pyenv/versions/3.11.3/lib/python3.11/site-packages/sqlalchemy/sql/elements.py", line 483, in _execute_on_connection
    return connection._execute_clauseelement(
           ^^^^^^^^^^^^^^^^^^^^^^^^^^^^^^^^^^
  File "/Users/dc/.pyenv/versions/3.11.3/lib/python3.11/site-packages/sqlalchemy/engine/base.py", line 1635, in _execute_clauseelement
    ret = self._execute_context(
          ^^^^^^^^^^^^^^^^^^^^^^
  File "/Users/dc/.pyenv/versions/3.11.3/lib/python3.11/site-packages/sqlalchemy/engine/base.py", line 1844, in _execute_context
    return self._exec_single_context(
           ^^^^^^^^^^^^^^^^^^^^^^^^^^
  File "/Users/dc/.pyenv/versions/3.11.3/lib/python3.11/site-packages/sqlalchemy/engine/base.py", line 1984, in _exec_single_context
    self._handle_dbapi_exception(
  File "/Users/dc/.pyenv/versions/3.11.3/lib/python3.11/site-packages/sqlalchemy/engine/base.py", line 2339, in _handle_dbapi_exception
    raise sqlalchemy_exception.with_traceback(exc_info[2]) from e
  File "/Users/dc/.pyenv/versions/3.11.3/lib/python3.11/site-packages/sqlalchemy/engine/base.py", line 1965, in _exec_single_context
    self.dialect.do_execute(
  File "/Users/dc/.pyenv/versions/3.11.3/lib/python3.11/site-packages/sqlalchemy/engine/default.py", line 921, in do_execute
    cursor.execute(statement, parameters)
sqlalchemy.exc.OperationalError: (sqlite3.OperationalError) attempt to write a readonly database
[SQL: UPDATE user SET last_seen=? WHERE user.id = ?]
[parameters: ('2023-08-07 01:45:35.151047', 2)]
(Background on this error at: https://sqlalche.me/e/20/e3q8)
2023-08-06 18:46:25,742 INFO: microblog startup [in /Users/dc/test_stuff/flask/ch9/microblog/app/__init__.py:39]
2023-08-06 18:46:30,536 INFO: microblog startup [in /Users/dc/test_stuff/flask/ch9/microblog/app/__init__.py:39]
2023-08-06 18:46:42,948 INFO: microblog startup [in /Users/dc/test_stuff/flask/ch9/microblog/app/__init__.py:39]
2023-08-06 18:46:56,549 INFO: microblog startup [in /Users/dc/test_stuff/flask/ch9/microblog/app/__init__.py:39]
